Traceback (most recent call last):
  File "C:\Users\ASUS A456UR\AppData\Local\Programs\Python\Python310\lib\site-packages\jupyter_cache\executors\utils.py", line 51, in single_nb_execution
    executenb(
  File "C:\Users\ASUS A456UR\AppData\Local\Programs\Python\Python310\lib\site-packages\nbclient\client.py", line 1204, in execute
    return NotebookClient(nb=nb, resources=resources, km=km, **kwargs).execute()
  File "C:\Users\ASUS A456UR\AppData\Local\Programs\Python\Python310\lib\site-packages\nbclient\util.py", line 84, in wrapped
    return just_run(coro(*args, **kwargs))
  File "C:\Users\ASUS A456UR\AppData\Local\Programs\Python\Python310\lib\site-packages\nbclient\util.py", line 62, in just_run
    return loop.run_until_complete(coro)
  File "C:\Users\ASUS A456UR\AppData\Local\Programs\Python\Python310\lib\asyncio\base_events.py", line 641, in run_until_complete
    return future.result()
  File "C:\Users\ASUS A456UR\AppData\Local\Programs\Python\Python310\lib\site-packages\nbclient\client.py", line 663, in async_execute
    await self.async_execute_cell(
  File "C:\Users\ASUS A456UR\AppData\Local\Programs\Python\Python310\lib\site-packages\nbclient\client.py", line 965, in async_execute_cell
    await self._check_raise_for_error(cell, cell_index, exec_reply)
  File "C:\Users\ASUS A456UR\AppData\Local\Programs\Python\Python310\lib\site-packages\nbclient\client.py", line 862, in _check_raise_for_error
    raise CellExecutionError.from_cell_and_msg(cell, exec_reply_content)
nbclient.exceptions.CellExecutionError: An error occurred while executing the following cell:
------------------
distortions = []
K = range(1,10)
for k in K:
    kmeanModel = KMeans(n_clusters=k)
    kmeanModel.fit(df_pca)
    distortions.append(kmeanModel.inertia_)
------------------

[1;31m---------------------------------------------------------------------------[0m
[1;31mNameError[0m                                 Traceback (most recent call last)
Input [1;32mIn [19][0m, in [0;36m<cell line: 3>[1;34m()[0m
[0;32m      3[0m [38;5;28;01mfor[39;00m k [38;5;129;01min[39;00m K:
[0;32m      4[0m     kmeanModel [38;5;241m=[39m KMeans(n_clusters[38;5;241m=[39mk)
[1;32m----> 5[0m     kmeanModel[38;5;241m.[39mfit([43mdf_pca[49m)
[0;32m      6[0m     distortions[38;5;241m.[39mappend(kmeanModel[38;5;241m.[39minertia_)

[1;31mNameError[0m: name 'df_pca' is not defined
NameError: name 'df_pca' is not defined

